<?xml version="1.0" encoding="utf-8"?>
<!-- This URDF was automatically created by SolidWorks to URDF Exporter! Originally created by Stephen Brawner (brawner@gmail.com) 
     Commit Version: 1.5.1-0-g916b5db  Build Version: 1.5.7152.31018
     For more information, please see http://wiki.ros.org/sw_urdf_exporter -->
<robot
  name="modelball">
  <link
    name="base_link">
    <inertial>
      <origin
        xyz="0.108922864318346 0.0847241760555163 -0.123403521783607"
        rpy="0 0 0" />
      <mass
        value="3.90118326560914" />
      <inertia
        ixx="0.0186236720310461"
        ixy="-3.31789538660945E-07"
        ixz="-1.46573682201631E-06"
        iyy="0.0179160741187242"
        iyz="-8.06514530953854E-06"
        izz="0.00875282674130429" />
    </inertial>
    <visual>
      <origin
        xyz="0 0 0"
        rpy="0 0 0" />
      <geometry>
        <mesh
          filename="package://modelball/meshes/base_link.STL" />
      </geometry>
      <material
        name="">
        <color
          rgba="0.752941176470588 0.752941176470588 0.752941176470588 1" />
      </material>
    </visual>
    <collision>
      <origin
        xyz="0 0 0"
        rpy="0 0 0" />
      <geometry>
        <mesh
          filename="package://modelball/meshes/base_link.STL" />
      </geometry>
    </collision>
  </link>
  <link
    name="LFS">
    <inertial>
      <origin
        xyz="-0.015694 0.017418 0.0073567"
        rpy="0 0 0" />
      <mass
        value="0.26437" />
      <inertia
        ixx="6.2915E-05"
        ixy="2.9641E-09"
        ixz="1.6485E-08"
        iyy="6.2207E-05"
        iyz="1.5645E-07"
        izz="3.2075E-05" />
    </inertial>
    <visual>
      <origin
        xyz="0 0 0"
        rpy="0 0 0" />
      <geometry>
        <mesh
          filename="package://modelball/meshes/LFS.STL" />
      </geometry>
      <material
        name="">
        <color
          rgba="0.75294 0.75294 0.75294 1" />
      </material>
    </visual>
    <collision>
      <origin
        xyz="0 0 0"
        rpy="0 0 0" />
      <geometry>
        <mesh
          filename="package://modelball/meshes/LFS.STL" />
      </geometry>
    </collision>
  </link>
  <joint
    name="LFS"
    type="prismatic">
    <origin
      xyz="0.24112 0.018826 0"
      rpy="0 1.5708 0" />
    <parent
      link="base_link" />
    <child
      link="LFS" />
    <axis
      xyz="1 0 0" />
    <limit
      lower="0"
      upper="0"
      effort="0"
      velocity="0" />
  </joint>
  <link
    name="LFW">
    <inertial>
      <origin
        xyz="0.015 1.7347E-18 -3.4694E-18"
        rpy="0 0 0" />
      <mass
        value="0.23932" />
      <inertia
        ixx="0.00030041"
        ixy="-7.4821E-37"
        ixz="-1.7791E-38"
        iyy="0.00016815"
        iyz="-1.541E-36"
        izz="0.00016815" />
    </inertial>
    <visual>
      <origin
        xyz="0 0 0"
        rpy="0 0 0" />
      <geometry>
        <mesh
          filename="package://modelball/meshes/LFW.STL" />
      </geometry>
      <material
        name="">
        <color
          rgba="1 1 1 1" />
      </material>
    </visual>
    <collision>
      <origin
        xyz="0 0 0"
        rpy="0 0 0" />
      <geometry>
        <mesh
          filename="package://modelball/meshes/LFW.STL" />
      </geometry>
    </collision>
  </link>
  <joint
    name="LFW"
    type="continuous">
    <origin
      xyz="0.014801 0.0046744 0.050633"
      rpy="1.5708 -1.5708 0" />
    <parent
      link="LFS" />
    <child
      link="LFW" />
    <axis
      xyz="1 0 0" />
    <limit
      effort="3.1"
      velocity="7" />
  </joint>
  <link
    name="RFS">
    <inertial>
      <origin
        xyz="-0.015685 0.017931 0.0073567"
        rpy="0 0 0" />
      <mass
        value="0.26437" />
      <inertia
        ixx="6.2915E-05"
        ixy="2.9641E-09"
        ixz="-1.6485E-08"
        iyy="6.2207E-05"
        iyz="-1.5645E-07"
        izz="3.2075E-05" />
    </inertial>
    <visual>
      <origin
        xyz="0 0 0"
        rpy="0 0 0" />
      <geometry>
        <mesh
          filename="package://modelball/meshes/RFS.STL" />
      </geometry>
      <material
        name="">
        <color
          rgba="0.75294 0.75294 0.75294 1" />
      </material>
    </visual>
    <collision>
      <origin
        xyz="0 0 0"
        rpy="0 0 0" />
      <geometry>
        <mesh
          filename="package://modelball/meshes/RFS.STL" />
      </geometry>
    </collision>
  </link>
  <joint
    name="RFS"
    type="prismatic">
    <origin
      xyz="-0.025117 0.054174 0"
      rpy="3.1416 1.5708 0" />
    <parent
      link="base_link" />
    <child
      link="RFS" />
    <axis
      xyz="1 0 0" />
    <limit
      lower="0"
      upper="0"
      effort="0"
      velocity="0" />
  </joint>
  <link
    name="RFW">
    <inertial>
      <origin
        xyz="-0.015 6.7654E-17 4.5103E-17"
        rpy="0 0 0" />
      <mass
        value="0.23932" />
      <inertia
        ixx="0.00030041"
        ixy="-2.4108E-37"
        ixz="9.0565E-37"
        iyy="0.00016815"
        iyz="-1.6941E-21"
        izz="0.00016815" />
    </inertial>
    <visual>
      <origin
        xyz="0 0 0"
        rpy="0 0 0" />
      <geometry>
        <mesh
          filename="package://modelball/meshes/RFW.STL" />
      </geometry>
      <material
        name="">
        <color
          rgba="1 1 1 1" />
      </material>
    </visual>
    <collision>
      <origin
        xyz="0 0 0"
        rpy="0 0 0" />
      <geometry>
        <mesh
          filename="package://modelball/meshes/RFW.STL" />
      </geometry>
    </collision>
  </link>
  <joint
    name="RFW"
    type="continuous">
    <origin
      xyz="0.014799 0.030674 0.050633"
      rpy="1.64 1.5708 0" />
    <parent
      link="RFS" />
    <child
      link="RFW" />
    <axis
      xyz="1 0 0" />
    <limit
      effort="3.1"
      velocity="7" />
  </joint>
  <link
    name="LBS">
    <inertial>
      <origin
        xyz="0.0023416 0.011605 0.0030325"
        rpy="0 0 0" />
      <mass
        value="0.18193" />
      <inertia
        ixx="0.00015842"
        ixy="3.541E-07"
        ixz="-1.5136E-20"
        iyy="0.0001879"
        iyz="-4.2486E-20"
        izz="0.00010696" />
    </inertial>
    <visual>
      <origin
        xyz="0 0 0"
        rpy="0 0 0" />
      <geometry>
        <mesh
          filename="package://modelball/meshes/LBS.STL" />
      </geometry>
      <material
        name="">
        <color
          rgba="0.75294 0.75294 0.75294 1" />
      </material>
    </visual>
    <collision>
      <origin
        xyz="0 0 0"
        rpy="0 0 0" />
      <geometry>
        <mesh
          filename="package://modelball/meshes/LBS.STL" />
      </geometry>
    </collision>
  </link>
  <joint
    name="LBS"
    type="prismatic">
    <origin
      xyz="0.28235 0.22575 0"
      rpy="3.1416 0 0" />
    <parent
      link="base_link" />
    <child
      link="LBS" />
    <axis
      xyz="0 0 1" />
    <limit
      lower="0"
      upper="0"
      effort="0"
      velocity="0" />
  </joint>
  <link
    name="RBS">
    <inertial>
      <origin
        xyz="0.0023416 0.011605 0.0030325"
        rpy="0 0 0" />
      <mass
        value="0.18193" />
      <inertia
        ixx="0.00015842"
        ixy="3.541E-07"
        ixz="1.4744E-21"
        iyy="0.0001879"
        iyz="-7.5198E-21"
        izz="0.00010696" />
    </inertial>
    <visual>
      <origin
        xyz="0 0 0"
        rpy="0 0 0" />
      <geometry>
        <mesh
          filename="package://modelball/meshes/RBS.STL" />
      </geometry>
      <material
        name="">
        <color
          rgba="0.75294 0.75294 0.75294 1" />
      </material>
    </visual>
    <collision>
      <origin
        xyz="0 0 0"
        rpy="0 0 0" />
      <geometry>
        <mesh
          filename="package://modelball/meshes/RBS.STL" />
      </geometry>
    </collision>
  </link>
  <joint
    name="RBS"
    type="prismatic">
    <origin
      xyz="-0.06635 0.20125 0"
      rpy="3.1416 0 3.1416" />
    <parent
      link="base_link" />
    <child
      link="RBS" />
    <axis
      xyz="0 0 1" />
    <limit
      lower="0"
      upper="0"
      effort="0"
      velocity="0" />
  </joint>
  <link
    name="fcam">
    <inertial>
      <origin
        xyz="0.049836 0.061784 0.068723"
        rpy="0 0 0" />
      <mass
        value="0.043612" />
      <inertia
        ixx="4.2948E-06"
        ixy="-8.8579E-10"
        ixz="-1.0181E-09"
        iyy="2.2106E-05"
        iyz="2.1758E-08"
        izz="2.3571E-05" />
    </inertial>
    <visual>
      <origin
        xyz="0 0 0"
        rpy="0 0 0" />
      <geometry>
        <mesh
          filename="package://modelball/meshes/fcam.STL" />
      </geometry>
      <material
        name="">
        <color
          rgba="0.79216 0.81961 0.93333 1" />
      </material>
    </visual>
    <collision>
      <origin
        xyz="0 0 0"
        rpy="0 0 0" />
      <geometry>
        <mesh
          filename="package://modelball/meshes/fcam.STL" />
      </geometry>
    </collision>
  </link>
  <joint
    name="fcam"
    type="fixed">
    <origin
      xyz="0.058161 0.080277 0.092507"
      rpy="1.5708 0 0" />
    <parent
      link="base_link" />
    <child
      link="fcam" />
    <axis
      xyz="0 0 0" />
  </joint>
  <link
    name="bcam">
    <inertial>
      <origin
        xyz="0.049836 0.061784 0.068723"
        rpy="0 0 0" />
      <mass
        value="0.043612" />
      <inertia
        ixx="4.2948E-06"
        ixy="-8.8548E-10"
        ixz="-1.0183E-09"
        iyy="2.2106E-05"
        iyz="2.1758E-08"
        izz="2.3571E-05" />
    </inertial>
    <visual>
      <origin
        xyz="0 0 0"
        rpy="0 0 0" />
      <geometry>
        <mesh
          filename="package://modelball/meshes/bcam.STL" />
      </geometry>
      <material
        name="">
        <color
          rgba="0.79216 0.81961 0.93333 1" />
      </material>
    </visual>
    <collision>
      <origin
        xyz="0 0 0"
        rpy="0 0 0" />
      <geometry>
        <mesh
          filename="package://modelball/meshes/bcam.STL" />
      </geometry>
    </collision>
  </link>
  <joint
    name="bcam"
    type="fixed">
    <origin
      xyz="0.058161 0.11013 0.12322"
      rpy="2.3562 0 0" />
    <parent
      link="base_link" />
    <child
      link="bcam" />
    <axis
      xyz="0 0 0" />
  </joint>
  <link
    name="Lidar">
    <inertial>
      <origin
        xyz="0 0 0"
        rpy="0 0 0" />
      <mass
        value="0" />
      <inertia
        ixx="0"
        ixy="0"
        ixz="0"
        iyy="0"
        iyz="0"
        izz="0" />
    </inertial>
    <visual>
      <origin
        xyz="0 0 0"
        rpy="0 0 0" />
      <geometry>
        <mesh
          filename="package://modelball/meshes/Lidar.STL" />
      </geometry>
      <material
        name="">
        <color
          rgba="1 1 1 1" />
      </material>
    </visual>
    <collision>
      <origin
        xyz="0 0 0"
        rpy="0 0 0" />
      <geometry>
        <mesh
          filename="package://modelball/meshes/Lidar.STL" />
      </geometry>
    </collision>
  </link>
  <joint
    name="Lidar"
    type="fixed">
    <origin
      xyz="0.24092 0.09856 -0.54869"
      rpy="-1.5708 0 -1.5708" />
    <parent
      link="base_link" />
    <child
      link="Lidar" />
    <axis
      xyz="0 0 0" />
  </joint>
</robot>